Workbook

Sheet Schema
A1: Spelschema F2013
A2: MV = målvakt · X = i truppen · grå = otillgänglig · tom = ledig. Genererat 2026-09-09 08:12
H4: MV | I4: MV | J4: MV | K4: MV | L4: 9M | M4: 9M | N4: M6 | O4: 9M | P4: H6 | Q4: V6 | R4: 9M | S4: M6 | T4: 9M | U4: 9M | V4: 9M | W4: M6 | X4: M6 | Y4: V6 | Z4: V6 | AA4: V6 | AB4: V6 | AC4: H6 | AD4: V6 | AE4: V6
H5: 1 | I5: 2 | J5: 3.75 | K5: 4 | L5: 1 | M5: 1.25 | N5: 1.5 | O5: 1.5 | P5: 1.5 | Q5: 1.75 | R5: 2 | S5: 2 | T5: 2 | U5: 2 | V5: 2.5 | W5: 3 | X5: 3 | Y5: 3 | Z5: 3.25 | AA5: 3.75 | AB5: 4 | AC5: 4 | AD5: 4 | AE5: 4
A6: Datum | B6: Dag | C6: Tid | D6: Nivå | E6: Match | F6: Spelplats | G6: Antal | H6: Freya Henley Hellström | I6: Irma Stål | J6: Irma Segerberg | K6: Nilla Davidsson | L6: Ella Fridberg | M6: Alicia Enström | N6: Gloria Klintefelt | O6: Sara Salkic | P6: Tyra Benjaminsson | Q6: Tyra Carlsson | R6: Felicia Sjöberg | S6: Lovisa Laggren | T6: Thilda Kangas | U6: Tilde Knoop | V6: Anna-Lisa Styrud | W6: Chloé Flodén | X6: Klara Bjurhede | Y6: Lova Wängvik | Z6: Ester Eliasson | AA6: Rihanna Jan Ali | AB6: Iza Aydin | AC6: Lykke Van Eijsden | AD6: Maja Jiveland | AE6: Sigrid Alströmer
A7: 2026-10-04 | B7: Söndag | C7: 13:15 | D7: Svår | E7: Alingsås HK 1 – IK Sävehof 1 | F7: Östlyckehallen Alingsås | G7: =COUNTIF(H7:AE7,"X")+COUNTIF(H7:AE7,"MV") -> 11 | I7: MV | L7: X | M7: X | N7: X | O7: X | P7: X | Q7: X | S7: X | T7: X | V7: X | W7: X
A8: 2026-10-10 | B8: Lördag | C8: 14:05 | D8: Lätt | E8: HK Lidköping 2 – Alingsås HK 2 | F8: Öjersjöhallen, Partille | G8: =COUNTIF(H8:AE8,"X")+COUNTIF(H8:AE8,"MV") -> 10 | I8: MV | P8: X | U8: X | V8: X | X8: X | Z8: X | AA8: X | AC8: X | AD8: X | AE8: X
A9: 2026-10-10 | B9: Lördag | C9: 15:35 | D9: Lätt | E9: IK Sävehof 2 – Alingsås HK 2 | F9: Öjersjöhallen, Partille | G9: =COUNTIF(H9:AE9,"X")+COUNTIF(H9:AE9,"MV") -> 10 | I9: MV | P9: X | U9: X | V9: X | X9: X | Z9: X | AA9: X | AC9: X | AD9: X | AE9: X
A10: 2026-10-11 | B10: Söndag | C10: 13:25 | D10: Svår | E10: IK Baltichov blå – Alingsås HK 1 | F10: Hjällsnäshallen B, Gråbo | G10: =COUNTIF(H10:AE10,"X")+COUNTIF(H10:AE10,"MV") -> 11 | I10: MV | L10: X | M10: X | N10: X | P10: X | Q10: X | R10: X | S10: X | T10: X | V10: X | W10: X
A11: 2026-10-24 | B11: Lördag | C11: 13:00 | D11: Svår | E11: Alingsås HK 1 – HK Aranäs Vit | F11: Alströmerhallen, Alingsås | G11: =COUNTIF(H11:AE11,"X")+COUNTIF(H11:AE11,"MV") -> 11 | H11: MV | L11: X | M11: X | N11: X | O11: X | P11: X | Q11: X | R11: X | S11: X | T11: X | X11: X
A12: 2026-10-25 | B12: Söndag | C12: 10:00 | D12: Lätt | E12: KFUM Trollhättan Nord – Alingsås HK 2 | F12: Torsbohallen, Trollhättan | G12: =COUNTIF(H12:AE12,"X")+COUNTIF(H12:AE12,"MV") -> 10 | K12: MV | O12: X | T12: X | W12: X | X12: X | Y12: X | Z12: X | AA12: X | AB12: X | AD12: X
A13: 2026-10-25 | B13: Söndag | C13: 11:20 | D13: Lätt | E13: Alingsås HK 2 – GF Kroppskultur 2 | F13: Torsbohallen, Trollhättan | G13: =COUNTIF(H13:AE13,"X")+COUNTIF(H13:AE13,"MV") -> 10 | K13: MV | O13: X | T13: X | W13: X | X13: X | Y13: X | Z13: X | AA13: X | AB13: X | AD13: X
A14: 2026-11-07 | B14: Lördag | C14: 12:45 | D14: Svår | E14: Habo HK Vit – Alingsås HK 1 | F14: Habo Sporthall C | G14: =COUNTIF(H14:AE14,"X")+COUNTIF(H14:AE14,"MV") -> 11 | I14: MV | L14: X | M14: X | N14: X | P14: X | Q14: X | R14: X | S14: X | T14: X | W14: X | Y14: X
A15: 2026-11-08 | B15: Söndag | C15: 12:00 | D15: Lätt | E15: Alingsås HK 2 – Stenungsunds HK Svart | F15: Östlyckehallen Alingsås | G15: =COUNTIF(H15:AE15,"X")+COUNTIF(H15:AE15,"MV") -> 10 | J15: MV | N15: X | P15: X | U15: X | V15: X | W15: X | AA15: X | AB15: X | AD15: X | AE15: X
A16: 2026-11-15 | B16: Söndag | C16: 13:00 | D16: Svår | E16: Skara HF Vit – Alingsås HK 1 | F16: Skara Idrottshall | G16: =COUNTIF(H16:AE16,"X")+COUNTIF(H16:AE16,"MV") -> 11 | I16: MV | L16: X | M16: X | N16: X | P16: X | Q16: X | R16: X | S16: X | U16: X | V16: X | Y16: X
A17: 2026-11-22 | B17: Söndag | C17: 11:15 | D17: Svår | E17: Alingsås HK 1 – HK Country Röd | F17: Nolhagahallen | G17: =COUNTIF(H17:AE17,"X")+COUNTIF(H17:AE17,"MV") -> 11 | H17: MV | L17: X | M17: X | N17: X | O17: X | P17: X | Q17: X | R17: X | S17: X | T17: X | Z17: X
A18: 2026-11-22 | B18: Söndag | C18: 15:45 | D18: Lätt | E18: IK Sävehof 2 – Alingsås HK 2 | F18: Idrottens Hus TH 1, Lidköping | G18: =COUNTIF(H18:AE18,"X")+COUNTIF(H18:AE18,"MV") -> 10 | J18: MV | U18: X | V18: X | W18: X | Y18: X | AA18: X | AB18: X | AC18: X | AD18: X | AE18: X
A19: 2026-11-22 | B19: Söndag | C19: 17:00 | D19: Lätt | E19: HK Lidköping 2 – Alingsås HK 2 | F19: Idrottens Hus TH 1, Lidköping | G19: =COUNTIF(H19:AE19,"X")+COUNTIF(H19:AE19,"MV") -> 10 | J19: MV | U19: X | V19: X | W19: X | Y19: X | AA19: X | AB19: X | AC19: X | AD19: X | AE19: X
A20: 2026-11-28 | B20: Lördag | C20: 16:45 | D20: Svår | E20: Skövde HF – Alingsås HK 1 | F20: Skövde Idrottshall | G20: =COUNTIF(H20:AE20,"X")+COUNTIF(H20:AE20,"MV") -> 11 | I20: MV | L20: X | M20: X | N20: X | P20: X | Q20: X | R20: X | S20: X | T20: X | W20: X | X20: X
A21: 2026-12-05 | B21: Lördag | C21: 10:00 | D21: Lätt | E21: Alingsås HK 2 – Kärra HF 2 | F21: Nolhagahallen | G21: =COUNTIF(H21:AE21,"X")+COUNTIF(H21:AE21,"MV") -> 10 | J21: MV | R21: X | V21: X | W21: X | X21: X | Z21: X | AA21: X | AB21: X | AC21: X | AE21: X
A22: 2026-12-05 | B22: Lördag | C22: 14:15 | D22: Lätt | E22: Alingsås HK 2 – Kungälvs HK Grön | F22: Nolhagahallen | G22: =COUNTIF(H22:AE22,"X")+COUNTIF(H22:AE22,"MV") -> 10 | J22: MV | R22: X | V22: X | W22: X | X22: X | Z22: X | AA22: X | AB22: X | AC22: X | AE22: X
A23: 2026-12-05 | B23: Lördag | C23: 15:15 | D23: Svår | E23: Alingsås HK 1 – Önnereds HK Grön | F23: Nolhagahallen | G23: =COUNTIF(H23:AE23,"X")+COUNTIF(H23:AE23,"MV") -> 11 | H23: MV | L23: X | M23: X | N23: X | O23: X | P23: X | Q23: X | S23: X | T23: X | U23: X | Y23: X
A24: 2026-12-20 | B24: Söndag | C24: 09:30 | D24: Lätt | E24: Kärra HF 2 – Alingsås HK 2 | F24: Angered Arena | G24: =COUNTIF(H24:AE24,"X")+COUNTIF(H24:AE24,"MV") -> 10 | K24: MV | R24: X | V24: X | X24: X | Y24: X | Z24: X | AA24: X | AB24: X | AC24: X | AD24: X
A25: 2026-12-20 | B25: Söndag | C25: 11:20 | D25: Lätt | E25: Alingsås HK 2 – Kungälvs HK Grön | F25: Angered Arena | G25: =COUNTIF(H25:AE25,"X")+COUNTIF(H25:AE25,"MV") -> 10 | K25: MV | R25: X | V25: X | X25: X | Y25: X | Z25: X | AA25: X | AB25: X | AC25: X | AD25: X
A26: 2026-12-20 | B26: Söndag | C26: 11:40 | D26: Svår | E26: Redbergslids IK Vit – Alingsås HK 1 | F26: Rosendalshallen A Göteborg | G26: =COUNTIF(H26:AE26,"X")+COUNTIF(H26:AE26,"MV") -> 11 | I26: MV | L26: X | M26: X | N26: X | O26: X | P26: X | Q26: X | S26: X | T26: X | U26: X | W26: X
A27: 2027-01-09 | B27: Lördag | C27: 11:00 | D27: Svår | E27: Alingsås HK 1 – Redbergslids IK Vit | F27: Östlyckehallen Alingsås | G27: =COUNTIF(H27:AE27,"X")+COUNTIF(H27:AE27,"MV") -> 11 | H27: MV | L27: X | M27: X | N27: X | O27: X | P27: X | Q27: X | S27: X | T27: X | U27: X | Z27: X
A28: 2027-01-09 | B28: Lördag | C28: 18:00 | D28: Lätt | E28: Stenungsunds HK Svart – Alingsås HK 2 | F28: Hallerna Idrottshall | G28: =COUNTIF(H28:AE28,"X")+COUNTIF(H28:AE28,"MV") -> 10 | K28: MV | R28: X | V28: X | W28: X | X28: X | Y28: X | AB28: X | AC28: X | AD28: X | AE28: X
A29: 2027-01-17 | B29: Söndag | C29: 12:15 | D29: Svår | E29: Önnereds HK Grön – Alingsås HK 1 | F29: ÖHK Gbg Brandservichallen | G29: =COUNTIF(H29:AE29,"X")+COUNTIF(H29:AE29,"MV") -> 11 | H29: MV | L29: X | M29: X | N29: X | P29: X | Q29: X | R29: X | S29: X | T29: X | U29: X | Y29: X
A30: 2027-01-23 | B30: Lördag | C30: 11:00 | D30: Svår | E30: Alingsås HK 1 – Skövde HF | F30: Östlyckehallen Alingsås | G30: =COUNTIF(H30:AE30,"X")+COUNTIF(H30:AE30,"MV") -> 11 | H30: MV | L30: X | M30: X | N30: X | O30: X | P30: X | Q30: X | R30: X | S30: X | U30: X | X30: X
A31: 2027-01-24 | B31: Söndag | C31: 10:00 | D31: Lätt | E31: Alingsås HK 2 – KFUM Trollhättan Nord | F31: Östlyckehallen Alingsås | G31: =COUNTIF(H31:AE31,"X")+COUNTIF(H31:AE31,"MV") -> 10 | K31: MV | O31: X | S31: X | V31: X | Y31: X | AA31: X | AB31: X | AC31: X | AD31: X | AE31: X
A32: 2027-01-24 | B32: Söndag | C32: 14:00 | D32: Lätt | E32: Alingsås HK 2 – GF Kroppskultur 2 | F32: Östlyckehallen Alingsås | G32: =COUNTIF(H32:AE32,"X")+COUNTIF(H32:AE32,"MV") -> 10 | K32: MV | O32: X | S32: X | V32: X | Y32: X | AA32: X | AB32: X | AC32: X | AD32: X | AE32: X
A33: 2027-01-31 | B33: Söndag | C33: 13:00 | D33: Svår | E33: HK Country Röd – Alingsås HK 1 | F33: Frösvehallen Stöpen | G33: =COUNTIF(H33:AE33,"X")+COUNTIF(H33:AE33,"MV") -> 11 | H33: MV | L33: X | M33: X | O33: X | Q33: X | R33: X | S33: X | T33: X | U33: X | X33: X | Z33: X
A34: 2027-02-06 | B34: Lördag | C34: 11:00 | D34: Svår | E34: Alingsås HK 1 – Skara HF Vit | F34: Östlyckehallen Alingsås | G34: =COUNTIF(H34:AE34,"X")+COUNTIF(H34:AE34,"MV") -> 11 | I34: MV | L34: X | M34: X | N34: X | O34: X | P34: X | Q34: X | S34: X | T34: X | U34: X | X34: X
A35: 2027-02-07 | B35: Söndag | C35: 13:40 | D35: Lätt | E35: Kungälvs HK Grön – Alingsås HK 2 | F35: Kungälvs Idrottshall | G35: =COUNTIF(H35:AE35,"X")+COUNTIF(H35:AE35,"MV") -> 10 | K35: MV | N35: X | O35: X | Q35: X | T35: X | X35: X | Y35: X | AC35: X | AD35: X | AE35: X
A36: 2027-02-07 | B36: Söndag | C36: 15:30 | D36: Lätt | E36: Alingsås HK 2 – Kärra HF 2 | F36: Kungälvs Idrottshall | G36: =COUNTIF(H36:AE36,"X")+COUNTIF(H36:AE36,"MV") -> 10 | K36: MV | N36: X | O36: X | Q36: X | T36: X | X36: X | Y36: X | AC36: X | AD36: X | AE36: X
A37: 2027-02-28 | B37: Söndag | C37: 10:00 | D37: Svår | E37: Alingsås HK 1 – Habo HK Vit | F37: Östlyckehallen Alingsås | G37: =COUNTIF(H37:AE37,"X")+COUNTIF(H37:AE37,"MV") -> 11 | H37: MV | L37: X | M37: X | N37: X | O37: X | P37: X | Q37: X | R37: X | S37: X | T37: X | U37: X
A38: 2027-03-06 | B38: Lördag | C38: 10:00 | D38: Lätt | E38: KFUM Trollhättan Nord – Alingsås HK 2 | F38: Torsbohallen, Trollhättan | G38: =COUNTIF(H38:AE38,"X")+COUNTIF(H38:AE38,"MV") -> 10 | J38: MV | O38: X | U38: X | W38: X | X38: X | Z38: X | AA38: X | AB38: X | AC38: X | AE38: X
A39: 2027-03-06 | B39: Lördag | C39: 11:20 | D39: Lätt | E39: Alingsås HK 2 – GF Kroppskultur 2 | F39: Torsbohallen, Trollhättan | G39: =COUNTIF(H39:AE39,"X")+COUNTIF(H39:AE39,"MV") -> 10 | J39: MV | O39: X | U39: X | W39: X | X39: X | Z39: X | AA39: X | AB39: X | AC39: X | AE39: X
A40: 2027-03-07 | B40: Söndag | C40: 16:45 | D40: Svår | E40: HK Aranäs Vit – Alingsås HK 1 | F40: Forsgläntans IH | G40: =COUNTIF(H40:AE40,"X")+COUNTIF(H40:AE40,"MV") -> 11 | I40: MV | L40: X | M40: X | N40: X | P40: X | R40: X | S40: X | T40: X | U40: X | V40: X | Z40: X
A41: 2027-03-14 | B41: Söndag | C41: 11:00 | D41: Svår | E41: Alingsås HK 1 – IK Baltichov blå | F41: Alströmerhallen, Alingsås | G41: =COUNTIF(H41:AE41,"X")+COUNTIF(H41:AE41,"MV") -> 11 | H41: MV | L41: X | M41: X | N41: X | O41: X | P41: X | Q41: X | S41: X | U41: X | V41: X | Z41: X
...

Sheet Per match
A1: Trupp per match
A3: Datum | B3: Dag | C3: Tid | D3: Nivå | E3: Matchnr | F3: Match | G3: Spelplats | H3: Målvakt | I3: Spelare 1 | J3: Spelare 2 | K3: Spelare 3 | L3: Spelare 4 | M3: Spelare 5 | N3: Spelare 6 | O3: Spelare 7 | P3: Spelare 8 | Q3: Spelare 9 | R3: Spelare 10 | S3: Spelare 11 | T3: Antal
A4: 2026-10-04 | B4: Söndag | C4: 13:15 | D4: Svår | E4: 26 5 1341 004 | F4: Alingsås HK 1 – IK Sävehof 1 | G4: Östlyckehallen Alingsås | H4: Irma Stål | I4: Tyra Benjaminsson | J4: Tyra Carlsson | K4: Alicia Enström | L4: Anna-Lisa Styrud | M4: Ella Fridberg | N4: Sara Salkic | O4: Thilda Kangas | P4: Chloé Flodén | Q4: Gloria Klintefelt | R4: Lovisa Laggren | T4: =COUNTA(H4:S4) -> 11
A5: 2026-10-10 | B5: Lördag | C5: 14:05 | D5: Lätt | E5: 26 5 1343 002 | F5: HK Lidköping 2 – Alingsås HK 2 | G5: Öjersjöhallen, Partille | H5: Irma Stål | I5: Ester Eliasson | J5: Lykke Van Eijsden | K5: Maja Jiveland | L5: Rihanna Jan Ali | M5: Sigrid Alströmer | N5: Tyra Benjaminsson | O5: Anna-Lisa Styrud | P5: Tilde Knoop | Q5: Klara Bjurhede | T5: =COUNTA(H5:S5) -> 10
A6: 2026-10-10 | B6: Lördag | C6: 15:35 | D6: Lätt | E6: 26 5 1343 003 | F6: IK Sävehof 2 – Alingsås HK 2 | G6: Öjersjöhallen, Partille | H6: Irma Stål | I6: Ester Eliasson | J6: Lykke Van Eijsden | K6: Maja Jiveland | L6: Rihanna Jan Ali | M6: Sigrid Alströmer | N6: Tyra Benjaminsson | O6: Anna-Lisa Styrud | P6: Tilde Knoop | Q6: Klara Bjurhede | T6: =COUNTA(H6:S6) -> 10
A7: 2026-10-11 | B7: Söndag | C7: 13:25 | D7: Svår | E7: 26 5 1341 006 | F7: IK Baltichov blå – Alingsås HK 1 | G7: Hjällsnäshallen B, Gråbo | H7: Irma Stål | I7: Tyra Benjaminsson | J7: Tyra Carlsson | K7: Alicia Enström | L7: Anna-Lisa Styrud | M7: Ella Fridberg | N7: Felicia Sjöberg | O7: Thilda Kangas | P7: Chloé Flodén | Q7: Gloria Klintefelt | R7: Lovisa Laggren | T7: =COUNTA(H7:S7) -> 11
A8: 2026-10-24 | B8: Lördag | C8: 13:00 | D8: Svår | E8: 26 5 1341 014 | F8: Alingsås HK 1 – HK Aranäs Vit | G8: Alströmerhallen, Alingsås | H8: Freya Henley Hellström | I8: Tyra Benjaminsson | J8: Tyra Carlsson | K8: Alicia Enström | L8: Ella Fridberg | M8: Felicia Sjöberg | N8: Sara Salkic | O8: Thilda Kangas | P8: Gloria Klintefelt | Q8: Klara Bjurhede | R8: Lovisa Laggren | T8: =COUNTA(H8:S8) -> 11
A9: 2026-10-25 | B9: Söndag | C9: 10:00 | D9: Lätt | E9: 26 5 1343 011 | F9: KFUM Trollhättan Nord – Alingsås HK 2 | G9: Torsbohallen, Trollhättan | H9: Nilla Davidsson | I9: Ester Eliasson | J9: Iza Aydin | K9: Lova Wängvik | L9: Maja Jiveland | M9: Rihanna Jan Ali | N9: Sara Salkic | O9: Thilda Kangas | P9: Chloé Flodén | Q9: Klara Bjurhede | T9: =COUNTA(H9:S9) -> 10
A10: 2026-10-25 | B10: Söndag | C10: 11:20 | D10: Lätt | E10: 26 5 1343 012 | F10: Alingsås HK 2 – GF Kroppskultur 2 | G10: Torsbohallen, Trollhättan | H10: Nilla Davidsson | I10: Ester Eliasson | J10: Iza Aydin | K10: Lova Wängvik | L10: Maja Jiveland | M10: Rihanna Jan Ali | N10: Sara Salkic | O10: Thilda Kangas | P10: Chloé Flodén | Q10: Klara Bjurhede | T10: =COUNTA(H10:S10) -> 10
A11: 2026-11-07 | B11: Lördag | C11: 12:45 | D11: Svår | E11: 26 5 1341 020 | F11: Habo HK Vit – Alingsås HK 1 | G11: Habo Sporthall C | H11: Irma Stål | I11: Lova Wängvik | J11: Tyra Benjaminsson | K11: Tyra Carlsson | L11: Alicia Enström | M11: Ella Fridberg | N11: Felicia Sjöberg | O11: Thilda Kangas | P11: Chloé Flodén | Q11: Gloria Klintefelt | R11: Lovisa Laggren | T11: =COUNTA(H11:S11) -> 11
A12: 2026-11-08 | B12: Söndag | C12: 12:00 | D12: Lätt | E12: 26 5 1343 021 | F12: Alingsås HK 2 – Stenungsunds HK Svart | G12: Östlyckehallen Alingsås | H12: Irma Segerberg | I12: Iza Aydin | J12: Maja Jiveland | K12: Rihanna Jan Ali | L12: Sigrid Alströmer | M12: Tyra Benjaminsson | N12: Anna-Lisa Styrud | O12: Tilde Knoop | P12: Chloé Flodén | Q12: Gloria Klintefelt | T12: =COUNTA(H12:S12) -> 10
A13: 2026-11-15 | B13: Söndag | C13: 13:00 | D13: Svår | E13: 26 5 1341 023 | F13: Skara HF Vit – Alingsås HK 1 | G13: Skara Idrottshall | H13: Irma Stål | I13: Lova Wängvik | J13: Tyra Benjaminsson | K13: Tyra Carlsson | L13: Alicia Enström | M13: Anna-Lisa Styrud | N13: Ella Fridberg | O13: Felicia Sjöberg | P13: Tilde Knoop | Q13: Gloria Klintefelt | R13: Lovisa Laggren | T13: =COUNTA(H13:S13) -> 11
A14: 2026-11-22 | B14: Söndag | C14: 11:15 | D14: Svår | E14: 26 5 1341 026 | F14: Alingsås HK 1 – HK Country Röd | G14: Nolhagahallen | H14: Freya Henley Hellström | I14: Ester Eliasson | J14: Tyra Benjaminsson | K14: Tyra Carlsson | L14: Alicia Enström | M14: Ella Fridberg | N14: Felicia Sjöberg | O14: Sara Salkic | P14: Thilda Kangas | Q14: Gloria Klintefelt | R14: Lovisa Laggren | T14: =COUNTA(H14:S14) -> 11
A15: 2026-11-22 | B15: Söndag | C15: 15:45 | D15: Lätt | E15: 26 5 1343 023 | F15: IK Sävehof 2 – Alingsås HK 2 | G15: Idrottens Hus TH 1, Lidköping | H15: Irma Segerberg | I15: Iza Aydin | J15: Lova Wängvik | K15: Lykke Van Eijsden | L15: Maja Jiveland | M15: Rihanna Jan Ali | N15: Sigrid Alströmer | O15: Anna-Lisa Styrud | P15: Tilde Knoop | Q15: Chloé Flodén | T15: =COUNTA(H15:S15) -> 10
A16: 2026-11-22 | B16: Söndag | C16: 17:00 | D16: Lätt | E16: 26 5 1343 024 | F16: HK Lidköping 2 – Alingsås HK 2 | G16: Idrottens Hus TH 1, Lidköping | H16: Irma Segerberg | I16: Iza Aydin | J16: Lova Wängvik | K16: Lykke Van Eijsden | L16: Maja Jiveland | M16: Rihanna Jan Ali | N16: Sigrid Alströmer | O16: Anna-Lisa Styrud | P16: Tilde Knoop | Q16: Chloé Flodén | T16: =COUNTA(H16:S16) -> 10
A17: 2026-11-28 | B17: Lördag | C17: 16:45 | D17: Svår | E17: 26 5 1341 031 | F17: Skövde HF – Alingsås HK 1 | G17: Skövde Idrottshall | H17: Irma Stål | I17: Tyra Benjaminsson | J17: Tyra Carlsson | K17: Alicia Enström | L17: Ella Fridberg | M17: Felicia Sjöberg | N17: Thilda Kangas | O17: Chloé Flodén | P17: Gloria Klintefelt | Q17: Klara Bjurhede | R17: Lovisa Laggren | T17: =COUNTA(H17:S17) -> 11
A18: 2026-12-05 | B18: Lördag | C18: 10:00 | D18: Lätt | E18: 26 5 1343 032 | F18: Alingsås HK 2 – Kärra HF 2 | G18: Nolhagahallen | H18: Irma Segerberg | I18: Ester Eliasson | J18: Iza Aydin | K18: Lykke Van Eijsden | L18: Rihanna Jan Ali | M18: Sigrid Alströmer | N18: Anna-Lisa Styrud | O18: Felicia Sjöberg | P18: Chloé Flodén | Q18: Klara Bjurhede | T18: =COUNTA(H18:S18) -> 10
A19: 2026-12-05 | B19: Lördag | C19: 14:15 | D19: Lätt | E19: 26 5 1343 034 | F19: Alingsås HK 2 – Kungälvs HK Grön | G19: Nolhagahallen | H19: Irma Segerberg | I19: Ester Eliasson | J19: Iza Aydin | K19: Lykke Van Eijsden | L19: Rihanna Jan Ali | M19: Sigrid Alströmer | N19: Anna-Lisa Styrud | O19: Felicia Sjöberg | P19: Chloé Flodén | Q19: Klara Bjurhede | T19: =COUNTA(H19:S19) -> 10
A20: 2026-12-05 | B20: Lördag | C20: 15:15 | D20: Svår | E20: 26 5 1341 037 | F20: Alingsås HK 1 – Önnereds HK Grön | G20: Nolhagahallen | H20: Freya Henley Hellström | I20: Lova Wängvik | J20: Tyra Benjaminsson | K20: Tyra Carlsson | L20: Alicia Enström | M20: Ella Fridberg | N20: Sara Salkic | O20: Thilda Kangas | P20: Tilde Knoop | Q20: Gloria Klintefelt | R20: Lovisa Laggren | T20: =COUNTA(H20:S20) -> 11
A21: 2026-12-20 | B21: Söndag | C21: 09:30 | D21: Lätt | E21: 26 5 1343 036 | F21: Kärra HF 2 – Alingsås HK 2 | G21: Angered Arena | H21: Nilla Davidsson | I21: Ester Eliasson | J21: Iza Aydin | K21: Lova Wängvik | L21: Lykke Van Eijsden | M21: Maja Jiveland | N21: Rihanna Jan Ali | O21: Anna-Lisa Styrud | P21: Felicia Sjöberg | Q21: Klara Bjurhede | T21: =COUNTA(H21:S21) -> 10
A22: 2026-12-20 | B22: Söndag | C22: 11:20 | D22: Lätt | E22: 26 5 1343 037 | F22: Alingsås HK 2 – Kungälvs HK Grön | G22: Angered Arena | H22: Nilla Davidsson | I22: Ester Eliasson | J22: Iza Aydin | K22: Lova Wängvik | L22: Lykke Van Eijsden | M22: Maja Jiveland | N22: Rihanna Jan Ali | O22: Anna-Lisa Styrud | P22: Felicia Sjöberg | Q22: Klara Bjurhede | T22: =COUNTA(H22:S22) -> 10
A23: 2026-12-20 | B23: Söndag | C23: 11:40 | D23: Svår | E23: 26 5 1341 044 | F23: Redbergslids IK Vit – Alingsås HK 1 | G23: Rosendalshallen A Göteborg | H23: Irma Stål | I23: Tyra Benjaminsson | J23: Tyra Carlsson | K23: Alicia Enström | L23: Ella Fridberg | M23: Sara Salkic | N23: Thilda Kangas | O23: Tilde Knoop | P23: Chloé Flodén | Q23: Gloria Klintefelt | R23: Lovisa Laggren | T23: =COUNTA(H23:S23) -> 11
A24: 2027-01-09 | B24: Lördag | C24: 11:00 | D24: Svår | E24: 26 5 1341 048 | F24: Alingsås HK 1 – Redbergslids IK Vit | G24: Östlyckehallen Alingsås | H24: Freya Henley Hellström | I24: Ester Eliasson | J24: Tyra Benjaminsson | K24: Tyra Carlsson | L24: Alicia Enström | M24: Ella Fridberg | N24: Sara Salkic | O24: Thilda Kangas | P24: Tilde Knoop | Q24: Gloria Klintefelt | R24: Lovisa Laggren | T24: =COUNTA(H24:S24) -> 11
A25: 2027-01-09 | B25: Lördag | C25: 18:00 | D25: Lätt | E25: 26 5 1343 049 | F25: Stenungsunds HK Svart – Alingsås HK 2 | G25: Hallerna Idrottshall | H25: Nilla Davidsson | I25: Iza Aydin | J25: Lova Wängvik | K25: Lykke Van Eijsden | L25: Maja Jiveland | M25: Sigrid Alströmer | N25: Anna-Lisa Styrud | O25: Felicia Sjöberg | P25: Chloé Flodén | Q25: Klara Bjurhede | T25: =COUNTA(H25:S25) -> 10
A26: 2027-01-17 | B26: Söndag | C26: 12:15 | D26: Svår | E26: 26 5 1341 055 | F26: Önnereds HK Grön – Alingsås HK 1 | G26: ÖHK Gbg Brandservichallen | H26: Freya Henley Hellström | I26: Lova Wängvik | J26: Tyra Benjaminsson | K26: Tyra Carlsson | L26: Alicia Enström | M26: Ella Fridberg | N26: Felicia Sjöberg | O26: Thilda Kangas | P26: Tilde Knoop | Q26: Gloria Klintefelt | R26: Lovisa Laggren | T26: =COUNTA(H26:S26) -> 11
A27: 2027-01-23 | B27: Lördag | C27: 11:00 | D27: Svår | E27: 26 5 1341 057 | F27: Alingsås HK 1 – Skövde HF | G27: Östlyckehallen Alingsås | H27: Freya Henley Hellström | I27: Tyra Benjaminsson | J27: Tyra Carlsson | K27: Alicia Enström | L27: Ella Fridberg | M27: Felicia Sjöberg | N27: Sara Salkic | O27: Tilde Knoop | P27: Gloria Klintefelt | Q27: Klara Bjurhede | R27: Lovisa Laggren | T27: =COUNTA(H27:S27) -> 11
A28: 2027-01-24 | B28: Söndag | C28: 10:00 | D28: Lätt | E28: 26 5 1343 050 | F28: Alingsås HK 2 – KFUM Trollhättan Nord | G28: Östlyckehallen Alingsås | H28: Nilla Davidsson | I28: Iza Aydin | J28: Lova Wängvik | K28: Lykke Van Eijsden | L28: Maja Jiveland | M28: Rihanna Jan Ali | N28: Sigrid Alströmer | O28: Anna-Lisa Styrud | P28: Sara Salkic | Q28: Lovisa Laggren | T28: =COUNTA(H28:S28) -> 10
A29: 2027-01-24 | B29: Söndag | C29: 14:00 | D29: Lätt | E29: 26 5 1343 052 | F29: Alingsås HK 2 – GF Kroppskultur 2 | G29: Östlyckehallen Alingsås | H29: Nilla Davidsson | I29: Iza Aydin | J29: Lova Wängvik | K29: Lykke Van Eijsden | L29: Maja Jiveland | M29: Rihanna Jan Ali | N29: Sigrid Alströmer | O29: Anna-Lisa Styrud | P29: Sara Salkic | Q29: Lovisa Laggren | T29: =COUNTA(H29:S29) -> 10
A30: 2027-01-31 | B30: Söndag | C30: 13:00 | D30: Svår | E30: 26 5 1341 062 | F30: HK Country Röd – Alingsås HK 1 | G30: Frösvehallen Stöpen | H30: Freya Henley Hellström | I30: Ester Eliasson | J30: Tyra Carlsson | K30: Alicia Enström | L30: Ella Fridberg | M30: Felicia Sjöberg | N30: Sara Salkic | O30: Thilda Kangas | P30: Tilde Knoop | Q30: Klara Bjurhede | R30: Lovisa Laggren | T30: =COUNTA(H30:S30) -> 11
A31: 2027-02-06 | B31: Lördag | C31: 11:00 | D31: Svår | E31: 26 5 1341 066 | F31: Alingsås HK 1 – Skara HF Vit | G31: Östlyckehallen Alingsås | H31: Irma Stål | I31: Tyra Benjaminsson | J31: Tyra Carlsson | K31: Alicia Enström | L31: Ella Fridberg | M31: Sara Salkic | N31: Thilda Kangas | O31: Tilde Knoop | P31: Gloria Klintefelt | Q31: Klara Bjurhede | R31: Lovisa Laggren | T31: =COUNTA(H31:S31) -> 11
A32: 2027-02-07 | B32: Söndag | C32: 13:40 | D32: Lätt | E32: 26 5 1343 060 | F32: Kungälvs HK Grön – Alingsås HK 2 | G32: Kungälvs Idrottshall | H32: Nilla Davidsson | I32: Lova Wängvik | J32: Lykke Van Eijsden | K32: Maja Jiveland | L32: Sigrid Alströmer | M32: Tyra Carlsson | N32: Sara Salkic | O32: Thilda Kangas | P32: Gloria Klintefelt | Q32: Klara Bjurhede | T32: =COUNTA(H32:S32) -> 10
A33: 2027-02-07 | B33: Söndag | C33: 15:30 | D33: Lätt | E33: 26 5 1343 061 | F33: Alingsås HK 2 – Kärra HF 2 | G33: Kungälvs Idrottshall | H33: Nilla Davidsson | I33: Lova Wängvik | J33: Lykke Van Eijsden | K33: Maja Jiveland | L33: Sigrid Alströmer | M33: Tyra Carlsson | N33: Sara Salkic | O33: Thilda Kangas | P33: Gloria Klintefelt | Q33: Klara Bjurhede | T33: =COUNTA(H33:S33) -> 10
A34: 2027-02-28 | B34: Söndag | C34: 10:00 | D34: Svår | E34: 26 5 1341 074 | F34: Alingsås HK 1 – Habo HK Vit | G34: Östlyckehallen Alingsås | H34: Freya Henley Hellström | I34: Tyra Benjaminsson | J34: Tyra Carlsson | K34: Alicia Enström | L34: Ella Fridberg | M34: Felicia Sjöberg | N34: Sara Salkic | O34: Thilda Kangas | P34: Tilde Knoop | Q34: Gloria Klintefelt | R34: Lovisa Laggren | T34: =COUNTA(H34:S34) -> 11
A35: 2027-03-06 | B35: Lördag | C35: 10:00 | D35: Lätt | E35: 26 5 1343 067 | F35: KFUM Trollhättan Nord – Alingsås HK 2 | G35: Torsbohallen, Trollhättan | H35: Irma Segerberg | I35: Ester Eliasson | J35: Iza Aydin | K35: Lykke Van Eijsden | L35: Rihanna Jan Ali | M35: Sigrid Alströmer | N35: Sara Salkic | O35: Tilde Knoop | P35: Chloé Flodén | Q35: Klara Bjurhede | T35: =COUNTA(H35:S35) -> 10
A36: 2027-03-06 | B36: Lördag | C36: 11:20 | D36: Lätt | E36: 26 5 1343 068 | F36: Alingsås HK 2 – GF Kroppskultur 2 | G36: Torsbohallen, Trollhättan | H36: Irma Segerberg | I36: Ester Eliasson | J36: Iza Aydin | K36: Lykke Van Eijsden | L36: Rihanna Jan Ali | M36: Sigrid Alströmer | N36: Sara Salkic | O36: Tilde Knoop | P36: Chloé Flodén | Q36: Klara Bjurhede | T36: =COUNTA(H36:S36) -> 10
A37: 2027-03-07 | B37: Söndag | C37: 16:45 | D37: Svår | E37: 26 5 1341 076 | F37: HK Aranäs Vit – Alingsås HK 1 | G37: Forsgläntans IH | H37: Irma Stål | I37: Ester Eliasson | J37: Tyra Benjaminsson | K37: Alicia Enström | L37: Anna-Lisa Styrud | M37: Ella Fridberg | N37: Felicia Sjöberg | O37: Thilda Kangas | P37: Tilde Knoop | Q37: Gloria Klintefelt | R37: Lovisa Laggren | T37: =COUNTA(H37:S37) -> 11
A38: 2027-03-14 | B38: Söndag | C38: 11:00 | D38: Svår | E38: 26 5 1341 084 | F38: Alingsås HK 1 – IK Baltichov blå | G38: Alströmerhallen, Alingsås | H38: Freya Henley Hellström | I38: Ester Eliasson | J38: Tyra Benjaminsson | K38: Tyra Carlsson | L38: Alicia Enström | M38: Anna-Lisa Styrud | N38: Ella Fridberg | O38: Sara Salkic | P38: Tilde Knoop | Q38: Gloria Klintefelt | R38: Lovisa Laggren | T38: =COUNTA(H38:S38) -> 11
A39: 2027-03-14 | B39: Söndag | C39: 15:15 | D39: Lätt | E39: 26 5 1343 077 | F39: Alingsås HK 2 – Stenungsunds HK Svart | G39: Alströmerhallen, Alingsås | H39: Irma Segerberg | I39: Iza Aydin | J39: Lova Wängvik | K39: Maja Jiveland | L39: Rihanna Jan Ali | M39: Sigrid Alströmer | N39: Felicia Sjöberg | O39: Thilda Kangas | P39: Chloé Flodén | Q39: Klara Bjurhede | T39: =COUNTA(H39:S39) -> 10
A40: 2027-03-21 | B40: Söndag | C40: 15:50 | D40: Lätt | E40: 26 5 1343 079 | F40: IK Sävehof 2 – Alingsås HK 2 | G40: Idrottens Hus TH 1, Lidköping | H40: Irma Segerberg | I40: Ester Eliasson | J40: Iza Aydin | K40: Lykke Van Eijsden | L40: Maja Jiveland | M40: Rihanna Jan Ali | N40: Sigrid Alströmer | O40: Anna-Lisa Styrud | P40: Felicia Sjöberg | Q40: Chloé Flodén | T40: =COUNTA(H40:S40) -> 10
A41: 2027-03-21 | B41: Söndag | C41: 16:55 | D41: Lätt | E41: 26 5 1343 080 | F41: HK Lidköping 2 – Alingsås HK 2 | G41: Idrottens Hus TH 1, Lidköping | H41: Irma Segerberg | I41: Ester Eliasson | J41: Iza Aydin | K41: Lykke Van Eijsden | L41: Maja Jiveland | M41: Rihanna Jan Ali | N41: Sigrid Alströmer | O41: Anna-Lisa Styrud | P41: Felicia Sjöberg | Q41: Chloé Flodén | T41: =COUNTA(H41:S41) -> 10
...

Sheet Uppdrag
A1: Föräldrauppdrag
A2: Namnet är barnets. Bara föräldrar vars barn spelar, ledarnas familjer undantagna.
A4: Truppenhet | B4: Datum | C4: Hemma/borta | D4: Match | E4: Spelplats | F4: Kiosk | G4: Matchvärd | H4: Sekretariat | I4: Körning
A5: S01 | B5: 2026-10-04 | C5: Hemma | D5: Alingsås HK 1 – IK Sävehof 1 | E5: Östlyckehallen Alingsås | F5: Chloé Flodén, Irma Stål | G5: Tyra Carlsson | H5: Anna-Lisa Styrud, Tyra Benjaminsson
A6: L01 | B6: 2026-10-10 | C6: Borta | D6: HK Lidköping 2 – Alingsås HK 2 / IK Sävehof 2 – Alingsås HK 2 | E6: Öjersjöhallen, Partille | I6: Anna-Lisa Styrud, Lykke Van Eijsden, Rihanna Jan Ali
A7: S02 | B7: 2026-10-11 | C7: Borta | D7: IK Baltichov blå – Alingsås HK 1 | E7: Hjällsnäshallen B, Gråbo | I7: Anna-Lisa Styrud, Chloé Flodén, Irma Stål
A8: S03 | B8: 2026-10-24 | C8: Hemma | D8: Alingsås HK 1 – HK Aranäs Vit | E8: Alströmerhallen, Alingsås | F8: Gloria Klintefelt, Lovisa Laggren | G8: Freya Henley Hellström | H8: Klara Bjurhede, Tyra Carlsson
A9: L02 | B9: 2026-10-25 | C9: Borta | D9: KFUM Trollhättan Nord – Alingsås HK 2 / Alingsås HK 2 – GF Kroppskultur 2 | E9: Torsbohallen, Trollhättan | I9: Klara Bjurhede, Maja Jiveland, Nilla Davidsson
A10: S04 | B10: 2026-11-07 | C10: Borta | D10: Habo HK Vit – Alingsås HK 1 | E10: Habo Sporthall C | I10: Chloé Flodén, Lova Wängvik, Tyra Benjaminsson
A11: L03 | B11: 2026-11-08 | C11: Hemma | D11: Alingsås HK 2 – Stenungsunds HK Svart | E11: Östlyckehallen Alingsås | F11: Maja Jiveland, Sigrid Alströmer | G11: Irma Segerberg | H11: Chloé Flodén, Rihanna Jan Ali
A12: S05 | B12: 2026-11-15 | C12: Borta | D12: Skara HF Vit – Alingsås HK 1 | E12: Skara Idrottshall | I12: Anna-Lisa Styrud, Irma Stål, Lova Wängvik
A13: S06 | B13: 2026-11-22 | C13: Hemma | D13: Alingsås HK 1 – HK Country Röd | E13: Nolhagahallen | F13: Freya Henley Hellström, Lovisa Laggren | G13: Gloria Klintefelt | H13: Ester Eliasson, Sara Salkic
A14: L04 | B14: 2026-11-22 | C14: Borta | D14: IK Sävehof 2 – Alingsås HK 2 / HK Lidköping 2 – Alingsås HK 2 | E14: Idrottens Hus TH 1, Lidköping | I14: Irma Segerberg, Lykke Van Eijsden, Sigrid Alströmer
A15: S07 | B15: 2026-11-28 | C15: Borta | D15: Skövde HF – Alingsås HK 1 | E15: Skövde Idrottshall | I15: Chloé Flodén, Irma Stål, Klara Bjurhede
A16: L05 | B16: 2026-12-05 | C16: Hemma | D16: Alingsås HK 2 – Kärra HF 2 / Alingsås HK 2 – Kungälvs HK Grön | E16: Nolhagahallen | F16: Rihanna Jan Ali, Sigrid Alströmer | G16: Lykke Van Eijsden | H16: Ester Eliasson, Irma Segerberg
A17: S08 | B17: 2026-12-05 | C17: Hemma | D17: Alingsås HK 1 – Önnereds HK Grön | E17: Nolhagahallen | F17: Lova Wängvik, Lovisa Laggren | G17: Gloria Klintefelt | H17: Tyra Benjaminsson, Tyra Carlsson
A18: L06 | B18: 2026-12-20 | C18: Borta | D18: Kärra HF 2 – Alingsås HK 2 / Alingsås HK 2 – Kungälvs HK Grön | E18: Angered Arena | I18: Lykke Van Eijsden, Maja Jiveland, Nilla Davidsson
A19: S09 | B19: 2026-12-20 | C19: Borta | D19: Redbergslids IK Vit – Alingsås HK 1 | E19: Rosendalshallen A Göteborg | I19: Chloé Flodén, Irma Stål, Sara Salkic
A20: S10 | B20: 2027-01-09 | C20: Hemma | D20: Alingsås HK 1 – Redbergslids IK Vit | E20: Östlyckehallen Alingsås | F20: Freya Henley Hellström, Sara Salkic | G20: Tyra Benjaminsson | H20: Ester Eliasson, Gloria Klintefelt
A21: L07 | B21: 2027-01-09 | C21: Borta | D21: Stenungsunds HK Svart – Alingsås HK 2 | E21: Hallerna Idrottshall | I21: Maja Jiveland, Nilla Davidsson, Sigrid Alströmer
A22: S11 | B22: 2027-01-17 | C22: Borta | D22: Önnereds HK Grön – Alingsås HK 1 | E22: ÖHK Gbg Brandservichallen | I22: Freya Henley Hellström, Lova Wängvik, Tyra Benjaminsson
A23: S12 | B23: 2027-01-23 | C23: Hemma | D23: Alingsås HK 1 – Skövde HF | E23: Östlyckehallen Alingsås | F23: Lovisa Laggren, Tyra Carlsson | G23: Klara Bjurhede | H23: Sara Salkic, Tyra Benjaminsson
A24: L08 | B24: 2027-01-24 | C24: Hemma | D24: Alingsås HK 2 – KFUM Trollhättan Nord / Alingsås HK 2 – GF Kroppskultur 2 | E24: Östlyckehallen Alingsås | F24: Maja Jiveland, Rihanna Jan Ali | G24: Lova Wängvik | H24: Lykke Van Eijsden, Nilla Davidsson
A25: S13 | B25: 2027-01-31 | C25: Borta | D25: HK Country Röd – Alingsås HK 1 | E25: Frösvehallen Stöpen | I25: Ester Eliasson, Freya Henley Hellström, Klara Bjurhede
A26: S14 | B26: 2027-02-06 | C26: Hemma | D26: Alingsås HK 1 – Skara HF Vit | E26: Östlyckehallen Alingsås | F26: Klara Bjurhede, Tyra Carlsson | G26: Sara Salkic | H26: Irma Stål, Lovisa Laggren
A27: L09 | B27: 2027-02-07 | C27: Borta | D27: Kungälvs HK Grön – Alingsås HK 2 / Alingsås HK 2 – Kärra HF 2 | E27: Kungälvs Idrottshall | I27: Lova Wängvik, Nilla Davidsson, Sigrid Alströmer
A28: S15 | B28: 2027-02-28 | C28: Hemma | D28: Alingsås HK 1 – Habo HK Vit | E28: Östlyckehallen Alingsås | F28: Freya Henley Hellström, Sara Salkic | G28: Lovisa Laggren | H28: Gloria Klintefelt, Tyra Carlsson
A29: L10 | B29: 2027-03-06 | C29: Borta | D29: KFUM Trollhättan Nord – Alingsås HK 2 / Alingsås HK 2 – GF Kroppskultur 2 | E29: Torsbohallen, Trollhättan | I29: Irma Segerberg, Lykke Van Eijsden, Rihanna Jan Ali
A30: S16 | B30: 2027-03-07 | C30: Borta | D30: HK Aranäs Vit – Alingsås HK 1 | E30: Forsgläntans IH | I30: Anna-Lisa Styrud, Ester Eliasson, Irma Stål
A31: S17 | B31: 2027-03-14 | C31: Hemma | D31: Alingsås HK 1 – IK Baltichov blå | E31: Alströmerhallen, Alingsås | F31: Gloria Klintefelt, Sara Salkic | G31: Anna-Lisa Styrud | H31: Ester Eliasson, Freya Henley Hellström
A32: L11 | B32: 2027-03-14 | C32: Hemma | D32: Alingsås HK 2 – Stenungsunds HK Svart | E32: Alströmerhallen, Alingsås | F32: Rihanna Jan Ali, Sigrid Alströmer | G32: Maja Jiveland | H32: Chloé Flodén, Irma Segerberg
A33: L12 | B33: 2027-03-21 | C33: Borta | D33: IK Sävehof 2 – Alingsås HK 2 / HK Lidköping 2 – Alingsås HK 2 | E33: Idrottens Hus TH 1, Lidköping | I33: Irma Segerberg, Lykke Van Eijsden, Rihanna Jan Ali
A34: S18 | B34: 2027-03-21 | C34: Borta | D34: IK Sävehof 1 – Alingsås HK 1 | E34: Partille Arena B | I34: Lova Wängvik, Tyra Benjaminsson, Tyra Carlsson

Sheet Per spelare
A1: Speltid per spelare
A3: Spelare | B3: Primär pos | C3: Nivå medel | D3: Grupp | E3: Svåra | F3: Lätta | G3: Totalt | H3: Frånvarande enheter | I3: Möjliga matcher | J3: Andel spelade | K3: Ledare | L3: Uppdrag
A4: Freya Henley Hellström | B4: MV | C4: 1 | D4: A | E4: =Schema!H46 -> 10 | F4: =Schema!H47 -> 0 | G4: =E4+F4 -> 10 | H4: 0 | I4: 18 | J4: =IF(I4=0,"",G4/I4) -> 0.55555556 | L4: 7
A5: Irma Stål | B5: MV | C5: 2 | D5: B | E5: =Schema!I46 -> 8 | F5: =Schema!I47 -> 2 | G5: =E5+F5 -> 10 | H5: 0 | I5: 39 | J5: =IF(I5=0,"",G5/I5) -> 0.25641026 | L5: 7
A6: Irma Segerberg | B6: MV | C6: 3.75 | D6: D | E6: =Schema!J46 -> 0 | F6: =Schema!J47 -> 10 | G6: =E6+F6 -> 10 | H6: 0 | I6: 21 | J6: =IF(I6=0,"",G6/I6) -> 0.47619048 | L6: 6
A7: Nilla Davidsson | B7: MV | C7: 4 | D7: D | E7: =Schema!K46 -> 0 | F7: =Schema!K47 -> 9 | G7: =E7+F7 -> 9 | H7: 0 | I7: 21 | J7: =IF(I7=0,"",G7/I7) -> 0.42857143 | L7: 5
A8: Ella Fridberg | B8: 9M | C8: 1 | D8: A | E8: =Schema!L46 -> 18 | F8: =Schema!L47 -> 0 | G8: =E8+F8 -> 18 | H8: 0 | I8: 18 | J8: =IF(I8=0,"",G8/I8) -> 1 | K8: Andreas
A9: Alicia Enström | B9: 9M | C9: 1.25 | D9: A | E9: =Schema!M46 -> 18 | F9: =Schema!M47 -> 0 | G9: =E9+F9 -> 18 | H9: 0 | I9: 18 | J9: =IF(I9=0,"",G9/I9) -> 1 | K9: Marcus
A10: Gloria Klintefelt | B10: M6 | C10: 1.5 | D10: B | E10: =Schema!N46 -> 17 | F10: =Schema!N47 -> 3 | G10: =E10+F10 -> 20 | H10: 0 | I10: 39 | J10: =IF(I10=0,"",G10/I10) -> 0.51282051 | L10: 6
A11: Sara Salkic | B11: 9M | C11: 1.5 | D11: B | E11: =Schema!O46 -> 12 | F11: =Schema!O47 -> 8 | G11: =E11+F11 -> 20 | H11: 0 | I11: 39 | J11: =IF(I11=0,"",G11/I11) -> 0.51282051 | L11: 7
A12: Tyra Benjaminsson | B12: H6 | C12: 1.5 | D12: B | E12: =Schema!P46 -> 17 | F12: =Schema!P47 -> 3 | G12: =E12+F12 -> 20 | H12: 0 | I12: 39 | J12: =IF(I12=0,"",G12/I12) -> 0.51282051 | L12: 7
A13: Tyra Carlsson | B13: V6 | C13: 1.75 | D13: B | E13: =Schema!Q46 -> 17 | F13: =Schema!Q47 -> 2 | G13: =E13+F13 -> 19 | H13: 0 | I13: 39 | J13: =IF(I13=0,"",G13/I13) -> 0.48717949 | L13: 7
A14: Felicia Sjöberg | B14: 9M | C14: 2 | D14: B | E14: =Schema!R46 -> 11 | F14: =Schema!R47 -> 8 | G14: =E14+F14 -> 19 | H14: 0 | I14: 39 | J14: =IF(I14=0,"",G14/I14) -> 0.48717949 | K14: Jehona
A15: Lovisa Laggren | B15: M6 | C15: 2 | D15: B | E15: =Schema!S46 -> 18 | F15: =Schema!S47 -> 2 | G15: =E15+F15 -> 20 | H15: 0 | I15: 39 | J15: =IF(I15=0,"",G15/I15) -> 0.51282051 | L15: 6
A16: Thilda Kangas | B16: 9M | C16: 2 | D16: B | E16: =Schema!T46 -> 15 | F16: =Schema!T47 -> 5 | G16: =E16+F16 -> 20 | H16: 0 | I16: 39 | J16: =IF(I16=0,"",G16/I16) -> 0.51282051 | K16: Ville
A17: Tilde Knoop | B17: 9M | C17: 2 | D17: B | E17: =Schema!U46 -> 12 | F17: =Schema!U47 -> 7 | G17: =E17+F17 -> 19 | H17: 0 | I17: 39 | J17: =IF(I17=0,"",G17/I17) -> 0.48717949 | K17: Erik
A18: Anna-Lisa Styrud | B18: 9M | C18: 2.5 | D18: C | E18: =Schema!V46 -> 5 | F18: =Schema!V47 -> 14 | G18: =E18+F18 -> 19 | H18: 0 | I18: 39 | J18: =IF(I18=0,"",G18/I18) -> 0.48717949 | L18: 6
A19: Chloé Flodén | B19: M6 | C19: 3 | D19: C | E19: =Schema!W46 -> 5 | F19: =Schema!W47 -> 13 | G19: =E19+F19 -> 18 | H19: 0 | I19: 39 | J19: =IF(I19=0,"",G19/I19) -> 0.46153846 | L19: 7
A20: Klara Bjurhede | B20: M6 | C20: 3 | D20: C | E20: =Schema!X46 -> 5 | F20: =Schema!X47 -> 14 | G20: =E20+F20 -> 19 | H20: 0 | I20: 39 | J20: =IF(I20=0,"",G20/I20) -> 0.48717949 | L20: 6
A21: Lova Wängvik | B21: V6 | C21: 3 | D21: C | E21: =Schema!Y46 -> 5 | F21: =Schema!Y47 -> 12 | G21: =E21+F21 -> 17 | H21: 0 | I21: 39 | J21: =IF(I21=0,"",G21/I21) -> 0.43589744 | L21: 7
A22: Ester Eliasson | B22: V6 | C22: 3.25 | D22: C | E22: =Schema!Z46 -> 5 | F22: =Schema!Z47 -> 12 | G22: =E22+F22 -> 17 | H22: 0 | I22: 39 | J22: =IF(I22=0,"",G22/I22) -> 0.43589744 | L22: 6
A23: Rihanna Jan Ali | B23: V6 | C23: 3.75 | D23: D | E23: =Schema!AA46 -> 0 | F23: =Schema!AA47 -> 18 | G23: =E23+F23 -> 18 | H23: 0 | I23: 21 | J23: =IF(I23=0,"",G23/I23) -> 0.85714286 | L23: 7
A24: Iza Aydin | B24: V6 | C24: 4 | D24: D | E24: =Schema!AB46 -> 0 | F24: =Schema!AB47 -> 17 | G24: =E24+F24 -> 17 | H24: 0 | I24: 21 | J24: =IF(I24=0,"",G24/I24) -> 0.80952381 | K24: Björn
A25: Lykke Van Eijsden | B25: H6 | C25: 4 | D25: D | E25: =Schema!AC46 -> 0 | F25: =Schema!AC47 -> 17 | G25: =E25+F25 -> 17 | H25: 0 | I25: 21 | J25: =IF(I25=0,"",G25/I25) -> 0.80952381 | L25: 7
A26: Maja Jiveland | B26: V6 | C26: 4 | D26: D | E26: =Schema!AD46 -> 0 | F26: =Schema!AD47 -> 17 | G26: =E26+F26 -> 17 | H26: 0 | I26: 21 | J26: =IF(I26=0,"",G26/I26) -> 0.80952381 | L26: 6
A27: Sigrid Alströmer | B27: V6 | C27: 4 | D27: D | E27: =Schema!AE46 -> 0 | F27: =Schema!AE47 -> 17 | G27: =E27+F27 -> 17 | H27: 0 | I27: 21 | J27: =IF(I27=0,"",G27/I27) -> 0.80952381 | L27: 6

Sheet Varningar
A1: Varningar
A3: Inga. Alla trupper kunde fyllas med önskat antal avbytare.
